Workbook

Sheet Users
A1: User_ID | B1: Email | C1: Password | D1: Role | E1: Full_Name | F1: Department | G1: Status
A2: USR012 | B2: phonethida.easygold@gmail.com | C2: easygold1234 | D2: Staff | E2: Phonethida Mangala | F2: MKT | G2: Active
A3: USR013 | B3: lvesaphong96@gmail.com | C3: easygold1234 | D3: Staff | E3: Souphavanh Vetsaphong | F3: MKT | G3: Active
A4: USR014 | B4: thavatxay94@gmail.com | C4: easygold1234 | D4: Staff | E4: Thavutxai Inthavongsa | F4: MKT | G4: Active
A5: USR015 | B5: Somparthana.bpv@gmail.com | C5: easygold1234 | D5: Warehouse | E5: Sompartthana Bouphavong | F5: BTL | G5: Active
A6: USR016 | B6: sout2017@gmail.com | C6: easygold1234 | D6: Warehouse | E6: Soudsada Keovongphet | F6: BTL | G6: Active
A7: USR017 | B7: tockppd@gmail.com | C7: easygold1234 | D7: Admin | E7: Nopphanai Phomphakdee | F7: MKT | G7: Active
A8: USR018 | B8: Jonathan.easygold@gmail.com | C8: easygold1234 | D8: Staff | E8: Jonathaan Meadley | F8: MKT | G8: Active
A9: USR019 | B9: sphengxay@gmail.com | C9: easygold1234 | D9: Director | E9: Souliphonh Phengxay | F9: MKT | G9: Active
A10: USR020 | B10: souphanithvst@gmail.com | C10: easygold1234 | D10: Admin | E10: Souphanit Vongsengthong | F10: MKT | G10: Active
A11: USR022 | B11: souk07025@gmail.com | C11: easygold1234 | D11: Staff | E11: Souk | F11: Admin | G11: Active
A12: USR023 | B12: cs@easygold.com | C12: easygold1234 | D12: Staff | E12: Customer Service | F12: CS | G12: Active
A13: u-1777371387680 | B13: souphavanh.vesaphong@gmail.com | C13: 1234 | D13: staff | E13: Linda | F13: MKT | G13: Active
A14: USR024 | B14: alounys08@gmail.com | C14: easygold1234 | D14: Line Manager | E14: Alouny | F14: MKT | G14: Active
A15: USR025 | B15: bm.keomath@gmail.com | C15: easygold1234 | D15: finance | E15: Bounmy | F15: Finance | G15: Active
A16: USR026 | B16: annasorsukun@gmail.com | C16: easygold9999 | D16: HR | E16: Anna | F16: HR | G16: Active
A17: USR027 | B17: malisa.pam1999@gmail.com | C17: easygold9999 | D17: PA | E17: Nuni | F17: PA | G17: Active
A18: u-1783691100280 | B18: soulinta2001@gmail.com | C18: 11223344 | D18: customer_service | E18: Soulinta | F18: Customer Service | G18: Active
A19: u-1783691100281 | B19: Saiyfonphommathed@gmail.com | C19: 11223344 | D19: customer_service | E19: Saiyfon | F19: Customer Service | G19: Active
A20: u-1783691100282 | B20: Baybiethammavong@gmail.com | C20: 11223344 | D20: customer_service | E20: Babie | F20: Customer Service | G20: Active

Sheet CS_SKU_MasterData
A1: SKU_ID | B1: Name | C1: Category | D1: Unit | E1: Opening_Balance | F1: Current_Stock | G1: Total_Inflow | H1: Low_Stock_Threshold | I1: Cost_Per_Unit | J1: Image | K1: CreatedAt
A2: sku-1771407897767 | B2: ກະເປົາເດີນທາງ | C2: Merch | D2: pcs | E2: 100 | F2: 100 | G2: 100 | H2: 1 | I2: 445000 | J2: https://drive.google.com/uc?id=1jqbe2VQorLQKzhEa70kLjQAK8IUk7SRM | K2: 46216
A3: sku-1771406960024 | B3: ບິກອີຊີໂກລ | C3: Merch | D3: pcs | E3: 1500 | F3: 1097 | G3: 1500 | H3: 10 | I3: 5000 | J3: https://drive.google.com/uc?id=1mGYB0oPqQFo3koTzQe1sBB2ytghlNPVQ | K3: 46216
A4: sku-1781681021177 | B4: ຫມວກ 2026 | C4: Merch | D4: ນ່ວຍ | E4: 500 | F4: 499 | G4: 500 | H4: 20 | I4: 55000 | J4: https://drive.google.com/uc?id=164-A6eQqvFJ8STTJlC3td3iRSKbspTKA | K4: 46216
A5: sku-1771407316677 | B5: ຄັນຮົ່ມ 2026 | C5: Merch | D5: pcs | E5: 200 | F5: 199 | G5: 200 | H5: 10 | I5: 84000 | J5: https://drive.google.com/uc?id=1ObA0rIgPSEiZtrqAul49v0r0EAaFv26e | K5: 46216
A6: sku-1780972510074 | B6: ຈອກເກັບອຸນຫະພູມ 2026 | C6: Merch | D6: ຫນ່ວຍ | E6: 300 | F6: 300 | G6: 300 | H6: 30 | I6: 73000 | J6: https://drive.google.com/uc?id=13U9QXzaW56b7drekeOZN2RrOiarFaTft | K6: 46216
A7: CS-SKU-1784195433787 | B7: ກ່ອງຄໍາ 2ສະຫລຶງ | C7: Merch | D7: ກ່ອງ | E7: 5 | F7: 5 | G7: 5 | H7: 3 | I7: 518000 | K7: 46219
A8: CS-SKU-1784195489874 | B8: ກ່ອງຄໍາ 2ບາດ | C8: Merch | D8: ກ່ອງ | E8: 5 | F8: 5 | G8: 5 | H8: 3 | I8: 518000 | K8: 46219
A9: CS-SKU-1784195540861 | B9: ກ່ອງຄໍາ 10ບາດ | C9: Merch | D9: ກ່ອງ | E9: 7 | F9: 6 | G9: 7 | H9: 4 | I9: 311000 | K9: 46219
A10: CS-SKU-1784195595962 | B10: ກ່ອງຄໍາ5ບາດ | C10: Merch | D10: ກ່ອງ | E10: 1 | F10: 0 | G10: 1 | H10: 0 | I10: 311000 | K10: 46219
A11: sku-1779434977945 | B11: Paper Bag | C11: Booth | D11: ອັນ | E11: 50 | F11: 50 | G11: 50 | H11: 100 | I11: 12000 | J11: https://drive.google.com/uc?id=1OKF2e1Rt7mP_J0eiuRSkTtDnZVTURAyO | K11: 46224
A12: sku-1785121215788 | B12: Paper Bag for GOLD | C12: Merch | D12: ອັນ | E12: 50 | F12: 50 | G12: 50 | H12: 500 | I12: 7000 | J12: https://drive.google.com/uc?id=1LB2DirspdcFj0fHC3XZOU64VHvO3gJ6M | K12: 46245

Sheet CS_Transactions
A1: ID | B1: Ticket_ID | C1: SKU_ID | D1: SKU_Name | E1: Qty | F1: Type | G1: Date | H1: Action_At | I1: Action_By | J1: Comment
B2: OPENING | C2: sku-1771407897767 | D2: ກະເປົາເດີນທາງ | E2: 100 | F2: addition | G2: 46216 | H2: 2026-07-13T03:46:26.360Z | I2: Customer Service | J2: Opening balance on SKU creation
B3: OPENING | C3: sku-1771406960024 | D3: ບິກອີຊີໂກລ | E3: 1500 | F3: addition | G3: 46216 | H3: 2026-07-13T03:46:30.776Z | I3: Customer Service | J3: Opening balance on SKU creation
B4: OPENING | C4: sku-1781681021177 | D4: ຫມວກ 2026 | E4: 500 | F4: addition | G4: 46216 | H4: 2026-07-13T03:46:33.457Z | I4: Customer Service | J4: Opening balance on SKU creation
B5: OPENING | C5: sku-1771407316677 | D5: ຄັນຮົ່ມ 2026 | E5: 200 | F5: addition | G5: 46216 | H5: 2026-07-13T03:46:35.934Z | I5: Customer Service | J5: Opening balance on SKU creation
B6: OPENING | C6: sku-1780972510074 | D6: ຈອກເກັບອຸນຫະພູມ 2026 | E6: 300 | F6: addition | G6: 46216 | H6: 2026-07-13T03:46:40.339Z | I6: Customer Service | J6: Opening balance on SKU creation
B7: OPENING | C7: CS-SKU-1784195239942 | D7: ກ່ອງຄໍາ 2ບາດ | E7: 5 | F7: addition | G7: 46219 | H7: 2026-07-16T09:47:20.522Z | I7: Babie | J7: Opening balance on SKU creation
B8: OPENING | C8: CS-SKU-1784195433787 | D8: ກ່ອງຄໍາ 2ສະຫລຶງ | E8: 5 | F8: addition | G8: 46219 | H8: 2026-07-16T09:50:34.239Z | I8: Babie | J8: Opening balance on SKU creation
B9: OPENING | C9: CS-SKU-1784195489874 | D9: ກ່ອງຄໍາ 2ບາດ | E9: 5 | F9: addition | G9: 46219 | H9: 2026-07-16T09:51:30.765Z | I9: Babie | J9: Opening balance on SKU creation
B10: OPENING | C10: CS-SKU-1784195540861 | D10: ກ່ອງຄໍາ 10ບາດ | E10: 7 | F10: addition | G10: 46219 | H10: 2026-07-16T09:52:21.691Z | I10: Babie | J10: Opening balance on SKU creation
B11: OPENING | C11: CS-SKU-1784195543750 | D11: ກ່ອງຄໍາ 10ບາດ | E11: 7 | F11: addition | G11: 46219 | H11: 2026-07-16T09:52:24.456Z | I11: Babie | J11: Opening balance on SKU creation
B12: OPENING | C12: CS-SKU-1784195595962 | D12: ກ່ອງຄໍາ5ບາດ | E12: 1 | F12: addition | G12: 46219 | H12: 2026-07-16T09:53:16.939Z | I12: Babie | J12: Opening balance on SKU creation
B13: OPENING | C13: sku-1779434977945 | D13: Paper Bag | E13: 50 | F13: addition | G13: 46224 | H13: 2026-07-21T09:30:12.439Z | I13: MKT Warehouse | J13: Auto-transferred from MKT WH - Ticket: TKT-1784194879118
... B21: DIRECT_DESTOCK | C21: sku-1771406960024 | D21: ບິກອີຊີໂກລ | E21: 400 | F21: deduction | G21: 46265 | H21: 2026-08-31T08:21:49.677Z | I21: Nopphanai Phomphakdee | J21: [MKT_TRANSFER] Return item today to MKT warehouse

Sheet System_Logs
A1: Timestamp | B1: Log
A2: 46099.743 | B2: Starting email notification for: TKT-1773830956566
A3: 46099.743 | B3: Recipients resolved: Somparthana.bpv@gmail.com,sout2017@gmail.com
A4: 46099.743 | B4: Fatal Email Error: Exception: ທ່ານບໍ່ໄດ້ຮັບອະນຸຍາດໃຫ້ເອີ້ນໃຊ້ MailApp.sendEmail. ຕ້ອງມີການອະນຸຍາດ: https://www.googleapis.com/auth/script.send_mail. ສຳລັບຂໍ້ມູນເພີ່ມເຕີມ, ກະລຸນາເບິ່ງ https://developers.google.com/apps-script/guides/support/troubleshooting#authorization-is
A5: 46099.747 | B5: Starting email notification for: TKT-1773831366323
A6: 46099.747 | B6: Recipients resolved: Somparthana.bpv@gmail.com,sout2017@gmail.com
A7: 46099.747 | B7: Email successfully sent to Somparthana.bpv@gmail.com,sout2017@gmail.com
A8: 46100.604 | B8: Starting email notification for: TKT-1773831366323
A9: 46100.604 | B9: Recipients resolved: Jonathan.easygold@gmail.com
A10: 46100.604 | B10: Email successfully sent to Jonathan.easygold@gmail.com
A11: 46100.692 | B11: Starting email notification for: TKT-1773831366323
A12: 46100.692 | B12: Recipients resolved: souk07025@gmail.com
A13: 46100.692 | B13: Email successfully sent to souk07025@gmail.com
... A541: 46184.609 | B541: Email successfully sent to sphengxay@gmail.com
A542: 46190.391 | B542: [SETTING] logSettingChange | C542: logSettingChange | D542: Nopphanai Phomphakdee | E542: admin | F542: Name: Test SKU added, Category: Merch, Unit: pcs, CPU: 10000
A543: 46190.392 | B543: [SETTING] logSettingChange | C543: logSettingChange | D543: Nopphanai Phomphakdee | E543: admin | F543: SKU: Test SKU added (sku-1781662984770), Qty: +15, Date: 2026-06-17, Remark: Test PO
A544: 46190.437 | B544: [SETTING] logSettingChange | C544: logSettingChange | D544: Sompartthana Bouphavong | E544: warehouse | F544: Name: Pride Bag, Category: Merch, Unit: ນ່ວຍ , CPU: 75000
A545: 46190.437 | B545: [SETTING] logSettingChange | C545: logSettingChange | D545: Sompartthana Bouphavong | E545: warehouse | F545: Name: Pride Bag, Category: Merch, Unit: ນ່ວຍ , CPU: 75000
A546: 46190.6 | B546: [SETTING] logSettingChange | C546: logSettingChange | D546: Sompartthana Bouphavong | E546: warehouse | F546: Name: ຫມວກ 2026 , Category: Merch, Unit: ນ່ວຍ, CPU: 55000
A547: 46191.666 | B547: Starting email notification for: TKT-1781773158812
A548: 46191.666 | B548: Recipients resolved: Somparthana.bpv@gmail.com,sout2017@gmail.com
A549: 46191.666 | B549: Email successfully sent to Somparthana.bpv@gmail.com,sout2017@gmail.com
A550: 46191.696 | B550: Starting email notification for: TKT-1781775750887
A551: 46191.696 | B551: Recipients resolved: Somparthana.bpv@gmail.com,sout2017@gmail.com
A552: 46191.696 | B552: Email successfully sent to Somparthana.bpv@gmail.com,sout2017@gmail.com
A553: 46191.704 | B553: Starting email notification for: TKT-1781776422307
A554: 46191.704 | B554: Recipients resolved: Somparthana.bpv@gmail.com,sout2017@gmail.com
A555: 46191.704 | B555: Email successfully sent to Somparthana.bpv@gmail.com,sout2017@gmail.com
A556: 46191.704 | B556: Starting email notification for: TKT-1781776426981
A557: 46191.704 | B557: Recipients resolved: Somparthana.bpv@gmail.com,sout2017@gmail.com
A558: 46191.704 | B558: Email successfully sent to Somparthana.bpv@gmail.com,sout2017@gmail.com
... A594: 46192.475 | B594: Email successfully sent to phonethida.easygold@gmail.com
A595: 46195.661 | B595: [SETTING] logSettingChange | C595: logSettingChange | D595: Sompartthana Bouphavong | E595: warehouse | F595: SKU: ບິກອີຊີໂກລ (sku-1771406960024), Qty: +1500, Date: 2026-06-22, Remark: WLH26006-017
A596: 46195.661 | B596: Starting email notification for: TKT-1781773158812
A597: 46195.661 | B597: Recipients resolved: alounys08@gmail.com
A598: 46195.661 | B598: Email successfully sent to alounys08@gmail.com
A599: 46195.662 | B599: Starting email notification for: TKT-1781775750887
A600: 46195.662 | B600: Recipients resolved: alounys08@gmail.com
A601: 46195.662 | B601: Email successfully sent to alounys08@gmail.com
A602: 46195.663 | B602: Starting email notification for: TKT-1781776426981
...

Sheet SKU_Remarks
A1: SKU_ID | B1: Remark | C1: Created_By | D1: User_Role | E1: Timestamp
A2: sku-1771407148002 | B2: Create 1 request for rebalance the stock | C2: Sompartthana | D2: warehouse | E2: 2026-02-19T06:35:04.867Z
A3: sku-1771407936514 | B3: Test 5 | C3: Sompartthana Bouphavong | D3: warehouse | E3: 2026-02-20T08:43:56.379Z

Sheet System_Config
A1: Key | B1: Value | C1: Description
A2: bypass_threshold | B2: 0
A3: bypass_level | B3: none

Sheet Categories
A1: Name
A2: Booth
A3: Merch

Sheet SKU_MasterData
A1: SKU_ID | B1: Name | C1: Category | D1: Unit | E1: Opening_Balance | F1: Current_stock | G1: Image | H1: Low_Stock_Threshold | I1: Total_Inflow | J1: Cost_Per_Unit | K1: createdAt
A2: sku-1771406960024 | B2: ບິກອີຊີໂກລ | C2: Merch | D2: pcs | E2: 850 | F2: 300 | G2: https://drive.google.com/uc?id=1mGYB0oPqQFo3koTzQe1sBB2ytghlNPVQ | H2: 10 | I2: 2750 | J2: 5000 | K2: 46073
A3: sku-1771407004896 | B3: ພວງກະເເຈ | C3: Merch | D3: pcs | E3: 474 | F3: 0 | G3: https://drive.google.com/uc?id=1qpRx9mvqdJ1XJNAI5A1Yum-S1kehd3JT | H3: 0 | I3: 474 | J3: 7000 | K3: 46073
A4: sku-1771407061986 | B4: ຈອກກາເເຟ | C4: Merch | D4: pcs | E4: 1637 | F4: 255 | G4: https://drive.google.com/uc?id=1AZ98F3nSd5kaWCpxmVUpcCCqiN98wEJw | H4: 0 | I4: 1637 | J4: 40000 | K4: 46073
A5: sku-1771407101349 | B5: ຈອກເກັບຄວາມເຢັນ | C5: Merch | D5: pcs | E5: 175 | F5: 0 | G5: https://drive.google.com/uc?id=1hkA1erHwgR0y9yNCPITVTAuQCOTRyx9S | H5: 0 | I5: 775 | J5: 73000 | K5: 46073
A6: sku-1771407148002 | B6: ກະເປົາຜ້າ | C6: Merch | D6: pcs | E6: 0 | F6: 0 | G6: https://drive.google.com/uc?id=1tuoXVXQvPsrEsQKVCgcgMSjemrSfN0qU | H6: 0 | I6: 0 | J6: 40000 | K6: 46073
A7: sku-1771407316677 | B7: ຄັນຮົ່ມ 2026 | C7: Merch | D7: pcs | E7: 0 | F7: 0 | G7: https://drive.google.com/uc?id=1ObA0rIgPSEiZtrqAul49v0r0EAaFv26e | H7: 10 | I7: 400 | J7: 84000 | K7: 46073
A8: sku-1771407810939 | B8: ກະປຸກອອມສິນ | C8: Merch | D8: pcs | E8: 392 | F8: 34 | G8: https://drive.google.com/uc?id=1zYF1oMDsGQ3SddvFHwy7669xUcjiamsj | H8: 0 | I8: 392 | J8: 59000 | K8: 46073
A9: sku-1771407856341 | B9: ຫມວກ | C9: Merch | D9: pcs | E9: 0 | F9: 0 | G9: https://drive.google.com/uc?id=1nWLOttjR5tBJbmtTx7xcsifZkj6NBZbu | H9: 0 | I9: 0 | J9: 53000 | K9: 46073
A10: sku-1771407897767 | B10: ກະເປົາເດີນທາງ | C10: Merch | D10: pcs | E10: 1 | F10: 100 | G10: https://drive.google.com/uc?id=1jqbe2VQorLQKzhEa70kLjQAK8IUk7SRM | H10: 1 | I10: 201 | J10: 445000 | K10: 46073
A11: sku-1771407936514 | B11: ຄັນຮົ່ມກ໊ອບ | C11: Merch | D11: pcs | E11: 98 | F11: 1 | G11: https://drive.google.com/uc?id=1iWhKjJRgOH7D1KyVmgx82NI1UeCB23Jk | H11: 1 | I11: 98 | J11: 180000 | K11: 46073
A12: sku-1771407974256 | B12: ຊຸດຈອກກາເຟ | C12: Merch | D12: set | E12: 310 | F12: 140 | G12: https://drive.google.com/uc?id=1BMRMe8whaL7XGIF_DnQPbYYIA_rozwqL | H12: 0 | I12: 310 | J12: 330000 | K12: 46073
A13: sku-1771408020353 | B13: ຊຸດພິນ້ຽມ (ປື້ມ+ຕຸກນ້ຳ+ບິກ) | C13: Merch | D13: set | E13: 120 | F13: 6 | G13: https://drive.google.com/uc?id=1yFnX4ALjzaH-hxAqslLLwl6y8PAC_1hN | H13: 0 | I13: 120 | J13: 251600 | K13: 46073
... A41: sku-1788146835376 | B41: Piggy Bank V2 | C41: Merch | D41: ອັນ | E41: 100 | F41: 100 | G41: https://drive.google.com/uc?id=1DO8XzALge_qHw41jw1x7ONsA2MYlMfIA | H41: 20 | I41: 100 | J41: 59000 | K41: 46262

Sheet Tickets
A1: ticket_id | B1: status | C1: Created_By | D1: Created_By_Name | E1: Department | F1: Delivery_Date | G1: Remark | H1: Created_At | I1: wh_comment | J1: lm_comment | K1: Director_Comment | L1: Actual Delivery Date | M1: Last_Action_At | N1: Last_Action_By | O1: Last_Action_Status | P1: Last_Action_Comment | Q1: Actual_Delivery_Date | R1: Type | S1: Return_Date
A2: TKT-1771577788359 | B2: finalized | C2: phonethida.easygold@gmail.com | D2: Phonethida Mangala | E2: {=_xlfn.XLOOKUP(C2,Users!B:B,Users!F:F)} -> MKT | F2: 46072 | G2: For Lunar New Year Campaign (10-17 Feb 2026) | H2: 2026-02-20T08:56:27.312Z | I2: Bam & J, ໄປເອົາຢູ່ສາງເອງ | M2: 2026-03-24T08:05:19.378Z | N2: Souliphonh Phengxay | O2: Approved | Q2: 46072 | R2: request
A3: TKT-1772507237246 | B3: finalized | C3: thavatxay94@gmail.com | D3: Thavutxai Inthavongsa | E3: {=_xlfn.XLOOKUP(C3,Users!B:B,Users!F:F)} -> MKT | F3: 46077 | G3: for Kaopoon's shooting as a prop and easter eggs | H3: 2026-03-03T03:07:14.742Z | M3: 2026-03-24T08:05:34.964Z | N3: Souliphonh Phengxay | O3: Approved | Q3: 46077 | R3: request
A4: TKT-1772592110294 | B4: finalized | C4: souk07025@gmail.com | D4: Souk | E4: {=_xlfn.XLOOKUP(C4,Users!B:B,Users!F:F)} -> Admin | F4: 46085 | G4: ເບີກໄປໃຊ້ຊັ້ນ 1 | H4: 2026-03-04T02:41:49.328Z | I4: ເບິກໂຕຈິ່ງແມ່ນ 20 ຊຸດ | M4: 2026-03-24T08:05:52.128Z | N4: Souliphonh Phengxay | O4: Approved | Q4: 46085 | R4: request
A5: TKT-1773299387291 | B5: finalized | C5: somparthana.bpv@gmail.com | D5: Sompartthana Bouphavong | E5: {=_xlfn.XLOOKUP(C5,Users!B:B,Users!F:F)} -> BTL | F5: 46093 | G5: ໃຫ້ທີມອາເຈັນຊີ້ ອອກບູສ ທີ່ງານ ຫນັງສື ຢູ່ ມ.ຊ | H5: 2026-03-12T07:09:46.109Z | M5: 2026-03-24T08:06:06.664Z | N5: Souliphonh Phengxay | O5: Approved | Q5: 46093 | R5: request
A6: TKT-1773652078809 | B6: finalized | C6: phonethida.easygold@gmail.com | D6: Phonethida Mangala | E6: {=_xlfn.XLOOKUP(C6,Users!B:B,Users!F:F)} -> MKT | F6: 46097 | G6: For Bluebox campaign | H6: 2026-03-16T09:07:56.326Z | M6: 2026-03-24T08:06:21.012Z | N6: Souliphonh Phengxay | O6: Approved | Q6: 46097 | R6: request
A7: TKT-1773722800507 | B7: finalized | C7: somparthana.bpv@gmail.com | D7: Sompartthana Bouphavong | E7: {=_xlfn.XLOOKUP(C7,Users!B:B,Users!F:F)} -> BTL | F7: 46094 | G7: ເບິກໄປຊັບພອດງານສະປອນເຊີ Pha-Jay | H7: 2026-03-17T04:46:39.165Z | M7: 2026-03-24T08:06:33.410Z | N7: Souliphonh Phengxay | O7: Approved | Q7: 46094 | R7: request
A8: TKT-1773723473614 | B8: finalized | C8: somparthana.bpv@gmail.com | D8: Sompartthana Bouphavong | E8: {=_xlfn.XLOOKUP(C8,Users!B:B,Users!F:F)} -> BTL | F8: 46098 | G8: Support Corporate (partnership) | H8: 2026-03-17T04:57:52.031Z | M8: 2026-03-24T08:07:06.618Z | N8: Souliphonh Phengxay | O8: Approved | Q8: 46098 | R8: request
A9: TKT-1774339252579 | B9: finalized | C9: somparthana.bpv@gmail.com | D9: Sompartthana Bouphavong | E9: {=_xlfn.XLOOKUP(C9,Users!B:B,Users!F:F)} -> BTL | F9: 46102 | G9: Agency support Picky Bank 40 | H9: 2026-03-24T08:00:51.245Z | M9: 2026-03-26T01:35:17.102Z | N9: Souliphonh Phengxay | O9: Approved | Q9: 46102 | R9: request
A10: TKT-1774431236031 | B10: finalized | C10: cs@easygold.com | D10: Customer Service | E10: {=_xlfn.XLOOKUP(C10,Users!B:B,Users!F:F)} -> CS | F10: 46106 | G10: ເບີກເຄື່ອງໄວ້ສາງຊັ້ນ6 | H10: 2026-03-25T09:33:54.102Z | I10: ນ້ອງໆ CX ເບິກມາໄວ້ຊັ້ນ 6 ເພື່ອມອບໃຫ້ລູກຄ້າທີ່ເຂົ້າມາແລກຄະແນນ | M10: 2026-03-27T01:36:19.060Z | N10: Souliphonh Phengxay | O10: Approved | Q10: 46106 | R10: request
A11: TKT-1774519787325 | B11: finalized | C11: souk07025@gmail.com | D11: Souk | E11: {=_xlfn.XLOOKUP(C11,Users!B:B,Users!F:F)} -> Admin | F11: 46107 | G11: ເບີກໄວ້ມອບໃຫ້ຫົວໜ້າກົມເຕັກໂນໂລຊີ ແລະ ໄວໃຫ້ແຂກຫົວໜ້າ | H11: 2026-03-26T10:09:45.687Z | I11: ເນື່ອງຈາກ ສຸກຕ້ອງການດ່ວນ (ມື້ຊັບມິດເລີຍ) ກໍ່ເລີຍໃຫ້ສຸກເບິກຢືມນຳທີມ ບໍລິການລູກຄ້າກ່ອນ, ແລ້ວປູນາຈະເບິກມາແທນຄືນໃຫ້ | M11: 2026-03-27T01:36:35.542Z | N11: Souliphonh Phengxay | O11: Approved | Q11: 46107 | R11: request
A12: TKT-1774519858761 | B12: finalized | C12: souk07025@gmail.com | D12: Souk | E12: {=_xlfn.XLOOKUP(C12,Users!B:B,Users!F:F)} -> Admin | F12: 46107 | G12: ໃຊ້ເປັນໂຕະກາເຟຊັ້ນ 01 ເພື່ອຮັບຮອງລູກຄ້າ | H12: 2026-03-26T10:10:55.935Z | M12: 2026-03-27T07:00:08.601Z | N12: Souliphonh Phengxay | O12: Approved | Q12: 46107 | R12: request
A13: TKT-1775030802941 | B13: finalized | C13: sout2017@gmail.com | D13: Soudsada Keovongphet | E13: {=_xlfn.XLOOKUP(C13,Users!B:B,Users!F:F)} -> BTL | F13: 46114 | G13: Free gifts and giveaways for customers at booth events. ເເຈກລູກຄ້າເປີດບັນຊີ ເເລະ ຊື້ຄຳຫນ້າບູດ | H13: 2026-04-01T08:06:38.832Z | J13: KPV Activation - Q2 | M13: 2026-04-01T10:48:36.679Z | N13: Souliphonh Phengxay | O13: Approved | Q13: 46114 | R13: request
A14: TKT-1775031095824 | B14: finalized | C14: sout2017@gmail.com | D14: Soudsada Keovongphet | E14: {=_xlfn.XLOOKUP(C14,Users!B:B,Users!F:F)} -> BTL | F14: 46114 | G14: Free gifts and giveaways for customers at booth events. ເເຈກລູກຄ້າເປີດບັນຊີໃຫມ່ ເເລະ ຊື້ຄຳຫນ້າບູດ | H14: 2026-04-01T08:11:29.309Z | J14: KPV Activation - Q2 | M14: 2026-04-01T10:48:57.282Z | N14: Souliphonh Phengxay | O14: Approved | Q14: 46114 | R14: request
A15: TKT-1775100401216 | B15: finalized | C15: somparthana.bpv@gmail.com | D15: Sompartthana Bouphavong | E15: {=_xlfn.XLOOKUP(C15,Users!B:B,Users!F:F)} -> BTL | F15: 46113 | G15: resubmit | H15: 2026-04-02T03:26:37.832Z | I15: ສຳລັບ ໄຕມາດ2 | M15: 2026-04-07T03:28:48.803Z | N15: Souliphonh Phengxay | O15: Approved | Q15: 46113 | R15: request
A16: TKT-1775528099100 | B16: finalized | C16: somparthana.bpv@gmail.com | D16: Sompartthana Bouphavong | E16: {=_xlfn.XLOOKUP(C16,Users!B:B,Users!F:F)} -> BTL | F16: 46119 | G16: For Q1 Booth activation by agency | H16: 2026-04-07T02:14:57.135Z | M16: 2026-04-20T09:52:15.946Z | N16: Souliphonh Phengxay | O16: Approved | Q16: 46119 | R16: request
A17: TKT-1775633130238 | B17: finalized | C17: cs@easygold.com | D17: Customer Service | E17: {=_xlfn.XLOOKUP(C17,Users!B:B,Users!F:F)} -> CS | F17: 46120 | G17: ເບີກເຄື່ອງໄວ້ສາງຊັ້ນ 6 | H17: 2026-04-08T07:25:25.225Z | I17: ໄດ້ເອົາເຄື່ອງຕົວຈິ່ງທີ່ມີທັງຫມົດ 70ກ້ານໃຫ້ເເລີຍ | M17: 2026-04-20T09:52:32.696Z | N17: Souliphonh Phengxay | O17: Approved | Q17: 46120 | R17: request
A18: TKT-1776670121981 | B18: finalized | C18: cs@easygold.com | D18: Customer Service | E18: {=_xlfn.XLOOKUP(C18,Users!B:B,Users!F:F)} -> CS | F18: 46122 | G18: ເບີກເຄື່ອງໄວ້ສາງຊັ້ນ 6 | H18: 2026-04-20T07:28:41.712Z | M18: 2026-04-21T08:22:30.059Z | N18: Souliphonh Phengxay | O18: Approved | Q18: 46122 | R18: request
A19: TKT-1776671610636 | B19: finalized | C19: somparthana.bpv@gmail.com | D19: Sompartthana Bouphavong | E19: {=_xlfn.XLOOKUP(C19,Users!B:B,Users!F:F)} -> BTL | F19: 46132 | G19: ເບິກໃຫ້ທີມງານການຕະຫລາດ, ພາດເນີຊີບ ແລະ ໂດ້ (ພະນັກງານເກົ່າ) | H19: 2026-04-20T07:53:29.444Z | M19: 2026-04-21T08:22:44.252Z | N19: Souliphonh Phengxay | O19: Approved | Q19: 46132 | R19: request
A20: TKT-1776671656947 | B20: finalized | C20: somparthana.bpv@gmail.com | D20: Sompartthana Bouphavong | E20: {=_xlfn.XLOOKUP(C20,Users!B:B,Users!F:F)} -> BTL | F20: 46132 | G20: ເບິກໃຫ້ທີມງານອາເຈັນຊີ້ ອອກບູສ | H20: 2026-04-20T07:54:15.631Z | M20: 2026-04-21T08:23:00.975Z | N20: Souliphonh Phengxay | O20: Approved | Q20: 46132 | R20: request
A21: TKT-1776756480752 | B21: finalized | C21: somparthana.bpv@gmail.com | D21: Sompartthana Bouphavong | E21: {=_xlfn.XLOOKUP(C21,Users!B:B,Users!F:F)} -> BTL | F21: 46132 | G21: ຊັບມິດຄືນ ເພຶ່ອຊັບພອດເຄມເປນ LNY | H21: 2026-04-21T07:27:59.520Z | M21: 2026-04-21T08:23:19.410Z | N21: Souliphonh Phengxay | O21: Approved | Q21: 46132 | R21: request
A22: TKT-1776829073779 | B22: finalized | C22: sout2017@gmail.com | D22: Soudsada Keovongphet | E22: {=_xlfn.XLOOKUP(C22,Users!B:B,Users!F:F)} -> BTL | F22: 46134 | G22: Free gifts and giveaways for customers at booth events.ເຄື່ອງເເຈກໃຫ້ລູກຄ້າຫນ້າບູດສາຂາວັງທອງ | H22: 2026-04-22T03:37:52.310Z | I22: ເພີ້ມເຕີມມີ: ແນວຕັ້ງໂທລະສັບ 10ອັນ ຫົວສາກ 10 ອັນ | M22: 2026-04-23T08:51:44.120Z | N22: Souliphonh Phengxay | O22: Approved | Q22: 46134 | R22: request
A23: TKT-1776927415197 | B23: finalized | C23: sout2017@gmail.com | D23: Soudsada Keovongphet | E23: {=_xlfn.XLOOKUP(C23,Users!B:B,Users!F:F)} -> BTL | F23: 46134 | G23: Free gifts and giveaways for customers at booth events. ເເຈກໃຫ້ກັບລູກຄ້າຫນ້າບູດສາຂາວັງທອງ | H23: 2026-04-23T06:56:53.725Z | I23: ເມເບິກໄປຊັບພອດບູສ ຫນ້າຮ້ານຄຳພູວົງ | M23: 2026-04-23T08:52:05.096Z | N23: Souliphonh Phengxay | O23: Approved | Q23: 46134 | R23: request
A24: TKT-1776927769965 | B24: finalized | C24: somparthana.bpv@gmail.com | D24: Sompartthana Bouphavong | E24: {=_xlfn.XLOOKUP(C24,Users!B:B,Users!F:F)} -> BTL | F24: 46134 | G24: ເບິກເຄື່ອງໃຫ້ອາເຈັນຊີ້ປະຈຳເດືອນ 5 ແລະ ເບິກໃຊ້ຊັບພອດງານ ອີເວັ້ນ StartUp 2026 | H24: 2026-04-23T07:02:48.592Z | I24: ຫມາຍເຫດ: ຄັນຮົ່ມກອຟ ເບິກໄປງານແລ້ວ, ແຕ່ບໍ່ທັນໄດ້ແຈກ ລໍຖ້າຜອລູ່ໃຫ້ຄຳເຫັນ | M24: 2026-04-23T08:52:24.977Z | N24: Souliphonh Phengxay | O24: Approved | Q24: 46134 | R24: request
A25: TKT-1776999501965 | B25: finalized | C25: souk07025@gmail.com | D25: Souk | E25: {=_xlfn.XLOOKUP(C25,Users!B:B,Users!F:F)} -> Admin | F25: 46135 | G25: ຍື່ມມາໃຫ້ລຸງຍາມ ,ອ້າຍນ້ອງຕຳຫຼວດ | H25: 2026-04-24T02:58:18.483Z | I25: ສຸກ, ໄດ້ໄປເບິກເອົາຢູ່ສາງເອງ ວັນທີ່ 23.04.2026 ຕອນເລິກວຽກ | M25: 2026-04-28T07:43:34.377Z | N25: Souliphonh Phengxay | O25: Approved | Q25: 46135 | R25: borrow
A26: TKT-1777276449750 | B26: finalized | C26: cs@easygold.com | D26: Customer Service | E26: {=_xlfn.XLOOKUP(C26,Users!B:B,Users!F:F)} -> CS | F26: 46139 | G26: ເບີດເຄື່ອງໄວ້ສາງຊັ້ນ 6 | H26: 2026-04-27T07:54:09.423Z | M26: 2026-04-28T07:45:30.211Z | N26: Souliphonh Phengxay | O26: Approved | Q26: 46139 | R26: request
A27: TKT-1777348190787 | B27: finalized | C27: cs@easygold.com | D27: Customer Service | E27: {=_xlfn.XLOOKUP(C27,Users!B:B,Users!F:F)} -> CS | F27: 46140 | G27: ເບີກເຄື່ອງໄວ້ສາງຊັ້ນ 6 | H27: 2026-04-28T03:49:49.600Z | I27: ບິກແມ່ນມີ4ກັບ, ກັບລະ 50ກ້ານ | M27: 2026-04-28T07:46:05.699Z | N27: Souliphonh Phengxay | O27: Approved | Q27: 46140 | R27: request
A28: TKT-1777355053398 | B28: finalized | C28: sout2017@gmail.com | D28: Soudsada Keovongphet | E28: {=_xlfn.XLOOKUP(C28,Users!B:B,Users!F:F)} -> BTL | F28: 46140 | G28: BTL ເບີກເຄື່ອງອອກບູດປະຈຳຫນ້າຮ້ານ 3ສາຂາ ເເລະ ເຄື່ອງເເຈກໃຫ້ບູດກິດຈະກຳຂອງທາງD-Day Agency | H28: 2026-04-28T05:44:11.757Z | M28: 2026-04-28T07:46:26.937Z | N28: Souliphonh Phengxay | O28: Approved | Q28: 46140 | R28: request
A29: TKT-1778045180113 | B29: finalized | C29: cs@easygold.com | D29: Customer Service | E29: CS | F29: 46147 | G29: ເບີກເຄື່ອງໄວ້ສາງຊັ້ນ 6 | H29: 2026-05-06T05:26:18.534Z | M29: 2026-05-12T04:33:22.044Z | N29: Alouny | O29: Approved | Q29: 46147 | R29: request
A30: TKT-1778230741215 | B30: finalized | C30: cs@easygold.com | D30: Customer Service | E30: MKT and CS | F30: 46150 | G30: ເບີກເຄື່ອງໄວ້ສາງຊັ້ນ6 | H30: 2026-05-08T08:58:59.313Z | M30: 2026-05-12T04:32:43.628Z | N30: Alouny | O30: Approved | Q30: 46150 | R30: request
A31: TKT-1778467898610 | B31: finalized | C31: souk07025@gmail.com | D31: Souk | E31: Admin | F31: 46153 | G31: ເບີກໃຫ້ກອງເລຂາ ຕອ້ນຮັບແຂກທາງຫ້ອງການ KPV | H31: 2026-05-11T02:51:34.125Z | I31: ຕາດຳພາເລຂາຫົວຫນ້າໄປຂົນເອົາເຄື່ອງຢູ່ສາງ | M31: 2026-05-12T04:34:47.745Z | N31: Alouny | O31: Approved | Q31: 46331 | R31: request
A32: TKT-1778469681143 | B32: finalized | C32: souk07025@gmail.com | D32: Souk | E32: Admin | F32: 46153 | G32: ໄວຮັບແຂກ ຜູ້ອຳນວຍການ | H32: 2026-05-11T03:21:13.404Z | I32: ສຸກ, ເບິກເອົາຊຸດຈອກກາເຟວ່າໄວ້ສາງຊັ້ນ 6 ເພື່ອໄວ້ຮັບແຂກ ແລະ ເພື່ອໄວ້ແຈກ ເບິກງວດທີ່ສອງ | M32: 2026-05-12T04:34:31.614Z | N32: Alouny | O32: Approved | Q32: 46331 | R32: request
A33: TKT-1778559259749 | B33: finalized | C33: cs@easygold.com | D33: Customer Service | E33: MKT and CS | F33: 46150 | G33: ເບີກເຄື່ອງໄວ້ໄຫ້ລູກຄ້າແລກ easy point | H33: 2026-05-12T04:14:18.498Z | I33: ໂຕນີ້, ແມ່ນເບິກໃຫ້ ທີມ CX ພິເສດ | M33: 2026-05-13T03:55:04.392Z | N33: Alouny | O33: Approved | Q33: 46150 | R33: request
A34: TKT-1778647133017 | B34: finalized | C34: cs@easygold.com | D34: Customer Service | E34: MKT and CS | F34: 46155 | G34: ເບີກເຄື່ອງໄວ້ໄຫ້ລູກຄ້າແລກ easy point | H34: 2026-05-13T04:38:51.479Z | M34: 2026-05-15T02:06:32.185Z | N34: Alouny | O34: Approved | Q34: 46155 | R34: request
A35: TKT-1778727782508 | B35: finalized | C35: thavatxay94@gmail.com | D35: Thavutxai Inthavongsa | E35: MKT | F35: 46156 | G35: BTL | H35: 2026-05-14T03:02:56.294Z | I35: *ຊຸດພິນ້ຽມ ເບິກມາງານ MOU x10 ເຫລືອນັ້ນແມ່ນເບິກມາໄວ້ໃຫ້ອາເຈັນຊີ້ອອກງານຊ່ວງເດືອນ 6 | M35: 2026-05-19T04:13:32.849Z | N35: Alouny | O35: Approved | Q35: 46156 | R35: request
A36: TKT-1778827318176 | B36: finalized | C36: phonethida.easygold@gmail.com | D36: Phonethida Mangala | E36: MKT and CS | F36: 46157 | G36: ເບີກເຄຶ່ອງແຄມເປນ Cashback | H36: 2026-05-15T06:41:57.350Z | I36: Resubmitte ເພາະທຳອິດຫລົງຊັບມິດເປັນເບິກເຄື່ອງຢືມ | M36: 2026-05-19T04:13:48.618Z | N36: Alouny | O36: Approved | Q36: 46157 | R36: request
A37: TKT-1779178137478 | B37: finalized | C37: cs@easygold.com | D37: Customer Service | E37: MKT and CS | F37: 46160 | G37: ເບີກເຄື່ອງໄວ້ສາງຊັ້ນ6 ໄວ້ໄຫ້ລູກຄ້າ easy point | H37: 2026-05-19T08:08:53.908Z | M37: 2026-05-26T03:11:45.043Z | N37: Alouny | O37: Approved | Q37: 46160 | R37: request
A38: TKT-1779336387407 | B38: finalized | C38: annasorsukun@gmail.com | D38: Anna | E38: HR | F38: 46169 | G38: Join Wii fair - Walk in interview event | H38: 2026-05-21T04:06:27.095Z | I38: HR ເບິກໄປຊັບພອດງານ 108job | M38: 2026-05-26T03:12:23.734Z | N38: Alouny | O38: Approved | Q38: 46169 | R38: request
A39: TKT-1779437242667 | B39: finalized | C39: cs@easygold.com | D39: Customer Service | E39: MKT and CS | F39: 46163 | G39: ເບີກໄວ້ໃສ່ເຄື່ອງໄຫ້ລູກຄ້າ | H39: 2026-05-22T08:07:21.414Z | I39: CX ເບິກໄວ້ໃສ່ເຄື່ອງໃຫ້ລູກຄ້າ | M39: 2026-05-26T03:11:17.051Z | N39: Alouny | O39: Approved | Q39: 46163 | R39: request
A40: TKT-1779776573671 | B40: finalized | C40: cs@easygold.com | D40: Customer Service | E40: MKT and CS | F40: 46167 | G40: ເບີກເຄື່ອງໄຫ້ລູກຄ້າ ແລກ easy point | H40: 2026-05-26T06:22:58.274Z | M40: 2026-06-19T04:21:55.114Z | N40: Souliphonh Phengxay | O40: Approved | Q40: 46167 | R40: request
...

Sheet TicketItems
A1: ticket_id | B1: sku_id | C1: SKU_Name | D1: qty_requested | E1: Qty_Approved | F1: Unit
A2: TKT-1771577788359 | B2: sku-1771407061986 | C2: ຈອກກາເເຟ | D2: 80 | E2: 80 | F2: pcs | G2: {=_xlfn.XLOOKUP(A2,Tickets!A:A,Tickets!B:B)} -> finalized | H2: {=_xlfn.xlookup(A2,Tickets!A:A,Tickets!G:G)} -> For Lunar New Year Campaign (10-17 Feb 2026)
A3: TKT-1771577788359 | B3: sku-1771407810939 | C3: ກະປຸກອອມສິນ | D3: 41 | E3: 41 | F3: pcs | G3: {=_xlfn.XLOOKUP(A3,Tickets!A:A,Tickets!B:B)} -> finalized | H3: {=_xlfn.xlookup(A3,Tickets!A:A,Tickets!G:G)} -> For Lunar New Year Campaign (10-17 Feb 2026)
A4: TKT-1772507237246 | B4: sku-1771406960024 | C4: ບິກອີຊີໂກລ | D4: 1 | E4: 1 | F4: pcs | G4: {=_xlfn.XLOOKUP(A4,Tickets!A:A,Tickets!B:B)} -> finalized | H4: {=_xlfn.xlookup(A4,Tickets!A:A,Tickets!G:G)} -> for Kaopoon's shooting as a prop and easter eggs
A5: TKT-1772507237246 | B5: sku-1771407004896 | C5: ພວງກະເເຈ | D5: 2 | E5: 2 | F5: pcs | G5: {=_xlfn.XLOOKUP(A5,Tickets!A:A,Tickets!B:B)} -> finalized | H5: {=_xlfn.xlookup(A5,Tickets!A:A,Tickets!G:G)} -> for Kaopoon's shooting as a prop and easter eggs
A6: TKT-1772507237246 | B6: sku-1771407101349 | C6: ຈອກເກັບຄວາມເຢັນ | D6: 1 | E6: 1 | F6: pcs | G6: {=_xlfn.XLOOKUP(A6,Tickets!A:A,Tickets!B:B)} -> finalized | H6: {=_xlfn.xlookup(A6,Tickets!A:A,Tickets!G:G)} -> for Kaopoon's shooting as a prop and easter eggs
A7: TKT-1772507237246 | B7: sku-1771407810939 | C7: ກະປຸກອອມສິນ | D7: 2 | E7: 2 | F7: pcs | G7: {=_xlfn.XLOOKUP(A7,Tickets!A:A,Tickets!B:B)} -> finalized | H7: {=_xlfn.xlookup(A7,Tickets!A:A,Tickets!G:G)} -> for Kaopoon's shooting as a prop and easter eggs
A8: TKT-1772592110294 | B8: sku-1771407061986 | C8: ຈອກກາເເຟ | D8: 10 | E8: 20 | F8: pcs | G8: {=_xlfn.XLOOKUP(A8,Tickets!A:A,Tickets!B:B)} -> finalized | H8: {=_xlfn.xlookup(A8,Tickets!A:A,Tickets!G:G)} -> ເບີກໄປໃຊ້ຊັ້ນ 1
A9: TKT-1773299387291 | B9: sku-1771407101349 | C9: ຈອກເກັບຄວາມເຢັນ | D9: 10 | E9: 10 | F9: pcs | G9: {=_xlfn.XLOOKUP(A9,Tickets!A:A,Tickets!B:B)} -> finalized | H9: {=_xlfn.xlookup(A9,Tickets!A:A,Tickets!G:G)} -> ໃຫ້ທີມອາເຈັນຊີ້ ອອກບູສ ທີ່ງານ ຫນັງສື ຢູ່ ມ.ຊ
A10: TKT-1773299387291 | B10: sku-1773299233699 | C10: A4 Brochure | D10: 1000 | E10: 1000 | F10: ອັນ | G10: {=_xlfn.XLOOKUP(A10,Tickets!A:A,Tickets!B:B)} -> finalized | H10: {=_xlfn.xlookup(A10,Tickets!A:A,Tickets!G:G)} -> ໃຫ້ທີມອາເຈັນຊີ້ ອອກບູສ ທີ່ງານ ຫນັງສື ຢູ່ ມ.ຊ
A11: TKT-1773652078809 | B11: sku-1771407061986 | C11: ຈອກກາເເຟ | D11: 30 | E11: 30 | F11: pcs | G11: {=_xlfn.XLOOKUP(A11,Tickets!A:A,Tickets!B:B)} -> finalized | H11: {=_xlfn.xlookup(A11,Tickets!A:A,Tickets!G:G)} -> For Bluebox campaign
A12: TKT-1773722800507 | B12: sku-1771408020353 | C12: ຊຸດພິນ້ຽມ (ປື້ມ+ຕຸກນ້ຳ+ບິກ) | D12: 5 | E12: 5 | F12: set | G12: {=_xlfn.XLOOKUP(A12,Tickets!A:A,Tickets!B:B)} -> finalized | H12: {=_xlfn.xlookup(A12,Tickets!A:A,Tickets!G:G)} -> ເບິກໄປຊັບພອດງານສະປອນເຊີ Pha-Jay
A13: TKT-1773723473614 | B13: sku-1771407101349 | C13: ຈອກເກັບຄວາມເຢັນ | D13: 10 | E13: 10 | F13: pcs | G13: {=_xlfn.XLOOKUP(A13,Tickets!A:A,Tickets!B:B)} -> finalized | H13: {=_xlfn.xlookup(A13,Tickets!A:A,Tickets!G:G)} -> Support Corporate (partnership)
... A86: TKT-1779336387407 | B86: sku-1771407061986 | C86: ຈອກກາເເຟ | D86: 3 | E86: 3 | F86: pcs | G86: {=_xlfn.XLOOKUP(A86,Tickets!A:A,Tickets!B:B)} -> finalized | H86: {=_xlfn.xlookup(A86,Tickets!A:A,Tickets!G:G)} -> Join Wii fair - Walk in interview event
A87: TKT-1779336387407 | B87: sku-1772183613706 | C87: Beach flag 310x240x60 Cm | D87: 2 | F87: ອັນ | G87: {=_xlfn.XLOOKUP(A87,Tickets!A:A,Tickets!B:B)} -> finalized | H87: {=_xlfn.xlookup(A87,Tickets!A:A,Tickets!G:G)} -> Join Wii fair - Walk in interview event
A88: TKT-1779437242667 | B88: sku-1779434977945 | C88: Paper Bag | D88: 70 | E88: 70 | F88: ອັນ | G88: {=_xlfn.XLOOKUP(A88,Tickets!A:A,Tickets!B:B)} -> finalized | H88: {=_xlfn.xlookup(A88,Tickets!A:A,Tickets!G:G)} -> ເບີກໄວ້ໃສ່ເຄື່ອງໄຫ້ລູກຄ້າ
A89: TKT-1779776573671 | B89: sku-1771407101349 | C89: ຈອກເກັບຄວາມເຢັນ | D89: 25 | E89: 25 | F89: pcs | G89: {=_xlfn.XLOOKUP(A89,Tickets!A:A,Tickets!B:B)} -> finalized | H89: {=_xlfn.xlookup(A89,Tickets!A:A,Tickets!G:G)} -> ເບີກເຄື່ອງໄຫ້ລູກຄ້າ ແລກ easy point
A90: TKT-1779776573671 | B90: sku-1771407810939 | C90: ກະປຸກອອມສິນ | D90: 1 | E90: 50 | F90: pcs | G90: {=_xlfn.XLOOKUP(A90,Tickets!A:A,Tickets!B:B)} -> finalized | H90: {=_xlfn.xlookup(A90,Tickets!A:A,Tickets!G:G)} -> ເບີກເຄື່ອງໄຫ້ລູກຄ້າ ແລກ easy point
A91: TKT-1779776573671 | B91: sku-1775456004647 | C91: ກະເປົາກິລາ | D91: 30 | E91: 30 | F91: ນ່ວຍ | G91: {=_xlfn.XLOOKUP(A91,Tickets!A:A,Tickets!B:B)} -> finalized | H91: {=_xlfn.xlookup(A91,Tickets!A:A,Tickets!G:G)} -> ເບີກເຄື່ອງໄຫ້ລູກຄ້າ ແລກ easy point
A92: TKT-1779776573671 | B92: sku-1771407897767 | C92: ກະເປົາເດີນທາງ | D92: 1 | E92: 1 | F92: pcs | G92: {=_xlfn.XLOOKUP(A92,Tickets!A:A,Tickets!B:B)} -> finalized | H92: {=_xlfn.xlookup(A92,Tickets!A:A,Tickets!G:G)} -> ເບີກເຄື່ອງໄຫ້ລູກຄ້າ ແລກ easy point
A93: TKT-1779776573671 | B93: sku-1774606011601 | C93: ຫົວສາກໂທລະສັບ | D93: 7 | E93: 7 | F93: ອັນ | G93: {=_xlfn.XLOOKUP(A93,Tickets!A:A,Tickets!B:B)} -> finalized | H93: {=_xlfn.xlookup(A93,Tickets!A:A,Tickets!G:G)} -> ເບີກເຄື່ອງໄຫ້ລູກຄ້າ ແລກ easy point
A94: TKT-1779876975030 | B94: sku-1771407004896 | C94: ພວງກະເເຈ | D94: 80 | E94: 135 | F94: pcs | G94: {=_xlfn.XLOOKUP(A94,Tickets!A:A,Tickets!B:B)} -> finalized | H94: {=_xlfn.xlookup(A94,Tickets!A:A,Tickets!G:G)} -> ເບີກເຄື່ອງໄຫ້ລູກຄ້າ ແລກ ອີຊີພ້ອຍ
A95: TKT-1779880791871 | B95: sku-1775456004647 | C95: ກະເປົາກິລາ | D95: 10 | E95: 10 | F95: ນ່ວຍ | G95: {=_xlfn.XLOOKUP(A95,Tickets!A:A,Tickets!B:B)} -> finalized | H95: {=_xlfn.xlookup(A95,Tickets!A:A,Tickets!G:G)} -> Campaign Lao Viet Bank ແຈກກະເປົ໋າ 10 ຫນ່ວຍ
A96: TKT-1779956511825 | B96: sku-1773828255894 | C96: JBL Speaker | D96: 1 | E96: 1 | F96: ນ່ວຍ | G96: {=_xlfn.XLOOKUP(A96,Tickets!A:A,Tickets!B:B)} -> returned | H96: {=_xlfn.xlookup(A96,Tickets!A:A,Tickets!G:G)} -> CDD at Suan Pruek Sa for CSR
A97: TKT-1780305786573 | B97: sku-1771408020353 | C97: ຊຸດພິນ້ຽມ (ປື້ມ+ຕຸກນ້ຳ+ບິກ) | D97: 5 | E97: 5 | F97: set | G97: {=_xlfn.XLOOKUP(A97,Tickets!A:A,Tickets!B:B)} -> finalized | H97: {=_xlfn.xlookup(A97,Tickets!A:A,Tickets!G:G)} -> Support Children's day campaign
A98: TKT-1780308974303 | B98: sku-1771407810939 | C98: ກະປຸກອອມສິນ | D98: 19 | E98: 19 | F98: pcs | G98: {=_xlfn.XLOOKUP(A98,Tickets!A:A,Tickets!B:B)} -> finalized | H98: {=_xlfn.xlookup(A98,Tickets!A:A,Tickets!G:G)} -> ລາຍການຊັບມິດອອກໃຫ້ອາເຈັນຊີ້ ແລະ ມອບໃຫ້ລູູກຄ້າຄະແນນລ້ານປ້າຍບາງສ່ວນ
A99: TKT-1780308974303 | B99: sku-1771407974256 | C99: ຊຸດຈອກກາເຟ | D99: 40 | E99: 40 | F99: set | G99: {=_xlfn.XLOOKUP(A99,Tickets!A:A,Tickets!B:B)} -> finalized | H99: {=_xlfn.xlookup(A99,Tickets!A:A,Tickets!G:G)} -> ລາຍການຊັບມິດອອກໃຫ້ອາເຈັນຊີ້ ແລະ ມອບໃຫ້ລູູກຄ້າຄະແນນລ້ານປ້າຍບາງສ່ວນ
... A112: TKT-1781083706105 | B112: sku-1771408020353 | C112: ຊຸດພິນ້ຽມ (ປື້ມ+ຕຸກນ້ຳ+ບິກ) | D112: 10 | E112: 10 | F112: set | G112: {=_xlfn.XLOOKUP(A112,Tickets!A:A,Tickets!B:B)} -> finalized | H112: {=_xlfn.xlookup(A112,Tickets!A:A,Tickets!G:G)} -> Giveaway for testimonial video shooting
A113: TKT-1781773158812 | B113: sku-1781666955837 | C113: Pride Bag | D113: 2 | E113: 2 | F113: ນ່ວຍ
A114: TKT-1781775750887 | B114: sku-1771408020353 | C114: ຊຸດພິນ້ຽມ (ປື້ມ+ຕຸກນ້ຳ+ບິກ) | D114: 5 | E114: 5 | F114: set
A115: TKT-1781775750887 | B115: sku-1775030698487 | C115: ສາຍຫ້ອຍຄໍ (ພວງກະແຈ) | D115: 100 | E115: 100 | F115: ອັນ
A116: TKT-1781776422307 | B116: sku-1781666955837 | C116: Pride Bag | D116: 70 | E116: 70 | F116: ນ່ວຍ
A117: TKT-1781776426981 | B117: sku-1781666955837 | C117: Pride Bag | D117: 30 | E117: 28 | F117: ນ່ວຍ
A118: TKT-1782183777297 | B118: sku-1771406960024 | C118: ບິກອີຊີໂກລ | D118: 1500 | E118: 1500 | F118: pcs
A119: TKT-1782183777297 | B119: sku-1771407316677 | C119: ຄັນຮົ່ມ 2026 | D119: 200 | E119: 200 | F119: pcs
A120: TKT-1782183777297 | B120: sku-1780972510074 | C120: ຈອກເກັບອຸນຫະພູມ 2026 | D120: 300 | E120: 300 | F120: ຫນ່ວຍ
A121: TKT-1782183777297 | B121: sku-1781681021177 | C121: ຫມວກ 2026 | D121: 500 | E121: 500 | F121: ນ່ວຍ
A122: TKT-1782703189783 | B122: sku-1771408020353 | C122: ຊຸດພິນ້ຽມ (ປື້ມ+ຕຸກນ້ຳ+ບິກ) | D122: 3 | E122: 3 | F122: set
A123: TKT-1782801962258 | B123: sku-1771407974256 | C123: ຊຸດຈອກກາເຟ | D123: 50 | E123: 50 | F123: set
A124: TKT-1783305053069 | B124: sku-1775456004647 | C124: ກະເປົາກິລາ | D124: 10 | E124: 10 | F124: ນ່ວຍ
...

Sheet StockTransactions
A1: ID | B1: Ticket_ID | C1: SKU_ID | D1: Qty | E1: Type | F1: Date | G1: Action_At | H1: Action_By | I1: Status | J1: Comment | K1: Qty_Broken | L1: SKU_Name
B2: TKT-1771577788359 | C2: sku-1771407061986 | D2: 80 | E2: deduction | F2: 46105 | G2: 2026-03-24T08:05:19.378Z | H2: Souliphonh Phengxay | I2: Approved
B3: TKT-1771577788359 | C3: sku-1771407810939 | D3: 41 | E3: deduction | F3: 46105 | G3: 2026-03-24T08:05:19.378Z | H3: Souliphonh Phengxay | I3: Approved
B4: TKT-1772507237246 | C4: sku-1771406960024 | D4: 1 | E4: deduction | F4: 46105 | G4: 2026-03-24T08:05:34.964Z | H4: Souliphonh Phengxay | I4: Approved
B5: TKT-1772507237246 | C5: sku-1771407004896 | D5: 2 | E5: deduction | F5: 46105 | G5: 2026-03-24T08:05:34.964Z | H5: Souliphonh Phengxay | I5: Approved
B6: TKT-1772507237246 | C6: sku-1771407101349 | D6: 1 | E6: deduction | F6: 46105 | G6: 2026-03-24T08:05:34.964Z | H6: Souliphonh Phengxay | I6: Approved
B7: TKT-1772507237246 | C7: sku-1771407810939 | D7: 2 | E7: deduction | F7: 46105 | G7: 2026-03-24T08:05:34.964Z | H7: Souliphonh Phengxay | I7: Approved
B8: TKT-1772592110294 | C8: sku-1771407061986 | D8: 20 | E8: deduction | F8: 46105 | G8: 2026-03-24T08:05:52.128Z | H8: Souliphonh Phengxay | I8: Approved
B9: TKT-1773299387291 | C9: sku-1771407101349 | D9: 10 | E9: deduction | F9: 46105 | G9: 2026-03-24T08:06:06.664Z | H9: Souliphonh Phengxay | I9: Approved
B10: TKT-1773299387291 | C10: sku-1773299233699 | D10: 1000 | E10: deduction | F10: 46105 | G10: 2026-03-24T08:06:06.664Z | H10: Souliphonh Phengxay | I10: Approved
B11: TKT-1773652078809 | C11: sku-1771407061986 | D11: 30 | E11: deduction | F11: 46105 | G11: 2026-03-24T08:06:21.012Z | H11: Souliphonh Phengxay | I11: Approved
B12: TKT-1773722800507 | C12: sku-1771408020353 | D12: 5 | E12: deduction | F12: 46105 | G12: 2026-03-24T08:06:33.410Z | H12: Souliphonh Phengxay | I12: Approved
B13: TKT-1773723473614 | C13: sku-1771407101349 | D13: 10 | E13: deduction | F13: 46105 | G13: 2026-03-24T08:07:06.618Z | H13: Souliphonh Phengxay | I13: Approved
... B73: TKT-1778559259749 | C73: sku-1775815774049 | D73: 100 | E73: deduction | F73: 46155 | G73: 2026-05-13T03:55:04.392Z | H73: Alouny | I73: Approved
B74: TKT-1778727782508 | C74: sku-1771407061986 | D74: 110 | E74: deduction | F74: 46157 | G74: 2026-05-15T02:05:50.241Z | H74: Alouny | I74: Approved | L74: ຈອກກາເເຟ
B75: TKT-1778727782508 | C75: sku-1771407101349 | D75: 10 | E75: deduction | F75: 46157 | G75: 2026-05-15T02:05:50.241Z | H75: Alouny | I75: Approved | L75: ຈອກເກັບຄວາມເຢັນ
B76: TKT-1778727782508 | C76: sku-1771407974256 | D76: 20 | E76: deduction | F76: 46157 | G76: 2026-05-15T02:05:50.241Z | H76: Alouny | I76: Approved | L76: ຊຸດຈອກກາເຟ
B77: TKT-1778647133017 | C77: sku-1771407810939 | D77: 50 | E77: deduction | F77: 46157 | G77: 2026-05-15T02:06:32.185Z | H77: Alouny | I77: Approved | L77: ກະປຸກອອມສິນ
B78: TKT-1778827318176 | C78: sku-1771407810939 | D78: 50 | E78: deduction | F78: 46157 | G78: 2026-05-15T06:44:59.862Z | H78: Sompartthana Bouphavong | I78: Booked | J78: Resubmitte ເພາະທຳອິດຫລົງຊັບມິດເປັນເບິກເຄື່ອງຢືມ | L78: ກະປຸກອອມສິນ
B79: TKT-1778827318176 | C79: sku-1771407061986 | D79: 50 | E79: deduction | F79: 46157 | G79: 2026-05-15T06:44:59.862Z | H79: Sompartthana Bouphavong | I79: Booked | J79: Resubmitte ເພາະທຳອິດຫລົງຊັບມິດເປັນເບິກເຄື່ອງຢືມ | L79: ຈອກກາເເຟ
B80: TKT-1779178137478 | C80: sku-1771407810939 | D80: 55 | E80: deduction | F80: 46161 | G80: 2026-05-19T08:34:09.587Z | H80: Sompartthana Bouphavong | I80: Booked | L80: ກະປຸກອອມສິນ
B81: TKT-1779178137478 | C81: sku-1771407061986 | D81: 400 | E81: deduction | F81: 46161 | G81: 2026-05-19T08:34:09.587Z | H81: Sompartthana Bouphavong | I81: Booked | L81: ຈອກກາເເຟ
B82: TKT-1779178137478 | C82: sku-1771407101349 | D82: 25 | E82: deduction | F82: 46161 | G82: 2026-05-19T08:34:09.587Z | H82: Sompartthana Bouphavong | I82: Booked | L82: ຈອກເກັບຄວາມເຢັນ
B83: TKT-1779336387407 | C83: sku-1772179915959 | D83: 1 | E83: deduction | F83: 46164 | G83: 2026-05-22T08:27:53.340Z | H83: Sompartthana Bouphavong | I83: Booked | J83: HR ເບິກໄປຊັບພອດງານ 108job | L83: ແບັກດອບແບບຜ້າ 230 WxH 200 cm
B84: TKT-1779336387407 | C84: sku-1771407004896 | D84: 50 | E84: deduction | F84: 46164 | G84: 2026-05-22T08:27:53.340Z | H84: Sompartthana Bouphavong | I84: Booked | J84: HR ເບິກໄປຊັບພອດງານ 108job | L84: ພວງກະເເຈ
B85: TKT-1779336387407 | C85: sku-1775030698487 | D85: 20 | E85: deduction | F85: 46164 | G85: 2026-05-22T08:27:53.340Z | H85: Sompartthana Bouphavong | I85: Booked | J85: HR ເບິກໄປຊັບພອດງານ 108job | L85: ສາຍຫ້ອຍຄໍ (ພວງກະແຈ)
B86: TKT-1779336387407 | C86: sku-1771407061986 | D86: 3 | E86: deduction | F86: 46164 | G86: 2026-05-22T08:27:53.340Z | H86: Sompartthana Bouphavong | I86: Booked | J86: HR ເບິກໄປຊັບພອດງານ 108job | L86: ຈອກກາເເຟ
B87: TKT-1779437242667 | C87: sku-1779434977945 | D87: 70 | E87: deduction | F87: 46164 | G87: 2026-05-22T08:28:49.497Z | H87: Sompartthana Bouphavong | I87: Booked | J87: CX ເບິກໄວ້ໃສ່ເຄື່ອງໃຫ້ລູກຄ້າ | L87: Paper Bag
B88: TKT-1779776573671 | C88: sku-1771407101349 | D88: 25 | E88: deduction | F88: 46170 | G88: 2026-05-28T09:41:15.944Z | H88: Sompartthana Bouphavong | I88: Booked | L88: ຈອກເກັບຄວາມເຢັນ
B89: TKT-1779776573671 | C89: sku-1771407810939 | D89: 50 | E89: deduction | F89: 46170 | G89: 2026-05-28T09:41:15.944Z | H89: Sompartthana Bouphavong | I89: Booked | L89: ກະປຸກອອມສິນ
B90: TKT-1779776573671 | C90: sku-1775456004647 | D90: 30 | E90: deduction | F90: 46170 | G90: 2026-05-28T09:41:15.944Z | H90: Sompartthana Bouphavong | I90: Booked | L90: ກະເປົາກິລາ
B91: TKT-1779776573671 | C91: sku-1771407897767 | D91: 1 | E91: deduction | F91: 46170 | G91: 2026-05-28T09:41:15.944Z | H91: Sompartthana Bouphavong | I91: Booked | L91: ກະເປົາເດີນທາງ
B92: TKT-1779776573671 | C92: sku-1774606011601 | D92: 7 | E92: deduction | F92: 46170 | G92: 2026-05-28T09:41:15.944Z | H92: Sompartthana Bouphavong | I92: Booked | L92: ຫົວສາກໂທລະສັບ
B93: TKT-1779876975030 | C93: sku-1771407004896 | D93: 135 | E93: deduction | F93: 46170 | G93: 2026-05-28T09:42:20.551Z | H93: Sompartthana Bouphavong | I93: Booked | J93: ເອື້ອຍປູນາ ເອົາໃຫ້ 80ອັນ ຕໍ່ມາ ອ້າຍຕາດຳເອົາເພີ້ມໃຫ້ອີກ 50ອັນ | L93: ພວງກະເເຈ
B94: TKT-1779880791871 | C94: sku-1775456004647 | D94: 10 | E94: deduction | F94: 46174 | G94: 2026-06-01T09:16:28.265Z | H94: Sompartthana Bouphavong | I94: Booked | L94: ກະເປົາກິລາ
B95: TKT-1780305786573 | C95: sku-1771408020353 | D95: 5 | E95: deduction | F95: 46174 | G95: 2026-06-01T09:24:09.244Z | H95: Sompartthana Bouphavong | I95: Booked | L95: ຊຸດພິນ້ຽມ (ປື້ມ+ຕຸກນ້ຳ+ບິກ)
B96: TKT-1780308974303 | C96: sku-1771407810939 | D96: 19 | E96: deduction | F96: 46174 | G96: 2026-06-01T10:26:37.118Z | H96: Sompartthana Bouphavong | I96: Booked | J96: Remark: ລາຍການຊັບມິດອອກໃຫ້ອາເຈັນຊີ້ ແລະ ມອບໃຫ້ລູູກຄ້າຄະແນນລ້ານປ້າຍບາງສ່ວນ | L96: ກະປຸກອອມສິນ
B97: TKT-1780308974303 | C97: sku-1771407974256 | D97: 40 | E97: deduction | F97: 46174 | G97: 2026-06-01T10:26:37.118Z | H97: Sompartthana Bouphavong | I97: Booked | J97: Remark: ລາຍການຊັບມິດອອກໃຫ້ອາເຈັນຊີ້ ແລະ ມອບໃຫ້ລູູກຄ້າຄະແນນລ້ານປ້າຍບາງສ່ວນ | L97: ຊຸດຈອກກາເຟ
B98: TKT-1780308974303 | C98: sku-1775815774049 | D98: 70 | E98: deduction | F98: 46174 | G98: 2026-06-01T10:26:37.118Z | H98: Sompartthana Bouphavong | I98: Booked | J98: Remark: ລາຍການຊັບມິດອອກໃຫ້ອາເຈັນຊີ້ ແລະ ມອບໃຫ້ລູູກຄ້າຄະແນນລ້ານປ້າຍບາງສ່ວນ | L98: ຂາຕັ້ງໂທລະສັບ
B99: TKT-1780308974303 | C99: sku-1775456004647 | D99: 9 | E99: deduction | F99: 46174 | G99: 2026-06-01T10:26:37.118Z | H99: Sompartthana Bouphavong | I99: Booked | J99: Remark: ລາຍການຊັບມິດອອກໃຫ້ອາເຈັນຊີ້ ແລະ ມອບໃຫ້ລູູກຄ້າຄະແນນລ້ານປ້າຍບາງສ່ວນ | L99: ກະເປົາກິລາ
...

Sheet TicketActions
A1: Action_ID | B1: Ticket_ID | C1: Action | D1: Status | E1: Action_At | F1: Action_By | G1: Comment | H1: Role
A2: act-1771577790156 | B2: TKT-1771577788359 | C2: Create | D2: Pending | E2: 2026-02-20T08:56:27.312Z | F2: Phonethida Mangala | G2: For Lunar New Year Campaign (10-17 Feb 2026) | I2: {=_xlfn.XLOOKUP(B2,Tickets!A:A,Tickets!A:A)} -> TKT-1771577788359
A3: act-1771577888542 | B3: TKT-1771577788359 | C3: Moved | D3: Moved | E3: 2026-02-20T08:58:06.250Z | F3: Sompartthana Bouphavong | G3: Bam & J, ໄປເອົາຢູ່ສາງເອງ | H3: warehouse | I3: {=_xlfn.XLOOKUP(B3,Tickets!A:A,Tickets!A:A)} -> TKT-1771577788359
A4: act-1771578447494 | B4: TKT-1771577788359 | C4: Approved | D4: Approved | E4: 2026-02-20T09:07:25.943Z | F4: Jonathaan Meadley | H4: line_manager | I4: {=_xlfn.XLOOKUP(B4,Tickets!A:A,Tickets!A:A)} -> TKT-1771577788359
A5: act-1771578449904 | B5: TKT-1771577788359 | C5: Approved | D5: Approved | E5: 2026-02-20T09:07:28.144Z | F5: Jonathaan Meadley | H5: line_manager | I5: {=_xlfn.XLOOKUP(B5,Tickets!A:A,Tickets!A:A)} -> TKT-1771577788359
A6: act-1772507240513 | B6: TKT-1772507237246 | C6: Create | D6: Pending | E6: 2026-03-03T03:07:14.742Z | F6: Thavutxai Inthavongsa | G6: for Kaopoon's shooting as a prop and easter eggs | I6: {=_xlfn.XLOOKUP(B6,Tickets!A:A,Tickets!A:A)} -> TKT-1772507237246
A7: act-1772592113645 | B7: TKT-1772592110294 | C7: Create | D7: Pending | E7: 2026-03-04T02:41:49.328Z | F7: Souk | G7: ເບີກໄປໃຊ້ຊັ້ນ 1 | I7: {=_xlfn.XLOOKUP(B7,Tickets!A:A,Tickets!A:A)} -> TKT-1772592110294
A8: act-1772597126104 | B8: TKT-1772592110294 | C8: Moved | D8: Moved | E8: 2026-03-04T04:05:26.103Z | G8: ເບິກໂຕຈິ່ງແມ່ນ 20 ຊຸດ | I8: {=_xlfn.XLOOKUP(B8,Tickets!A:A,Tickets!A:A)} -> TKT-1772592110294
A9: act-1772597313959 | B9: TKT-1772507237246 | C9: Moved | D9: Moved | E9: 2026-03-04T04:08:33.958Z | I9: {=_xlfn.XLOOKUP(B9,Tickets!A:A,Tickets!A:A)} -> TKT-1772507237246
A10: act-1773299389251 | B10: TKT-1773299387291 | C10: Create | D10: Pending | E10: 2026-03-12T07:09:46.109Z | F10: Sompartthana Bouphavong | G10: ໃຫ້ທີມອາເຈັນຊີ້ ອອກບູສ ທີ່ງານ ຫນັງສື ຢູ່ ມ.ຊ | I10: {=_xlfn.XLOOKUP(B10,Tickets!A:A,Tickets!A:A)} -> TKT-1773299387291
A11: act-1773299423281 | B11: TKT-1773299387291 | C11: Moved | D11: Moved | E11: 2026-03-12T07:10:23.280Z | I11: {=_xlfn.XLOOKUP(B11,Tickets!A:A,Tickets!A:A)} -> TKT-1773299387291
A12: act-1773652080538 | B12: TKT-1773652078809 | C12: Create | D12: Pending | E12: 2026-03-16T09:07:56.326Z | F12: Phonethida Mangala | G12: For Bluebox campaign | I12: {=_xlfn.XLOOKUP(B12,Tickets!A:A,Tickets!A:A)} -> TKT-1773652078809
A13: act-1773722472511 | B13: TKT-1773652078809 | C13: Moved | D13: Moved | E13: 2026-03-17T04:41:10.408Z | F13: Sompartthana Bouphavong | H13: warehouse | I13: {=_xlfn.XLOOKUP(B13,Tickets!A:A,Tickets!A:A)} -> TKT-1773652078809
A14: act-1773722802937 | B14: TKT-1773722800507 | C14: Create | D14: Pending | E14: 2026-03-17T04:46:39.165Z | F14: Sompartthana Bouphavong | G14: ເບິກໄປຊັບພອດງານສະປອນເຊີ Pha-Jay | I14: {=_xlfn.XLOOKUP(B14,Tickets!A:A,Tickets!A:A)} -> TKT-1773722800507
A15: act-1773722814948 | B15: TKT-1773722800507 | C15: Moved | D15: Moved | E15: 2026-03-17T04:46:52.162Z | F15: Sompartthana Bouphavong | H15: warehouse | I15: {=_xlfn.XLOOKUP(B15,Tickets!A:A,Tickets!A:A)} -> TKT-1773722800507
A16: act-1773723476271 | B16: TKT-1773723473614 | C16: Create | D16: Pending | E16: 2026-03-17T04:57:52.031Z | F16: Sompartthana Bouphavong | G16: Support Corporate (partnership) | I16: {=_xlfn.XLOOKUP(B16,Tickets!A:A,Tickets!A:A)} -> TKT-1773723473614
A17: act-1773728269600 | B17: TKT-1772507237246 | C17: Approved | D17: Approved | E17: 2026-03-17T06:17:46.257Z | F17: Jonathaan Meadley | H17: line_manager | I17: {=_xlfn.XLOOKUP(B17,Tickets!A:A,Tickets!A:A)} -> TKT-1772507237246
A18: act-1773728284530 | B18: TKT-1772592110294 | C18: Approved | D18: Approved | E18: 2026-03-17T06:18:00.410Z | F18: Jonathaan Meadley | H18: line_manager | I18: {=_xlfn.XLOOKUP(B18,Tickets!A:A,Tickets!A:A)} -> TKT-1772592110294
A19: act-1773728293440 | B19: TKT-1773299387291 | C19: Approved | D19: Approved | E19: 2026-03-17T06:18:11.442Z | F19: Jonathaan Meadley | H19: line_manager | I19: {=_xlfn.XLOOKUP(B19,Tickets!A:A,Tickets!A:A)} -> TKT-1773299387291
A20: act-1773728300840 | B20: TKT-1773652078809 | C20: Approved | D20: Approved | E20: 2026-03-17T06:18:18.868Z | F20: Jonathaan Meadley | H20: line_manager | I20: {=_xlfn.XLOOKUP(B20,Tickets!A:A,Tickets!A:A)} -> TKT-1773652078809
A21: act-1773728305746 | B21: TKT-1773722800507 | C21: Approved | D21: Approved | E21: 2026-03-17T06:18:23.750Z | F21: Jonathaan Meadley | H21: line_manager | I21: {=_xlfn.XLOOKUP(B21,Tickets!A:A,Tickets!A:A)} -> TKT-1773722800507
A22: act-1773728691096 | B22: TKT-1773723473614 | C22: Moved | D22: Moved | E22: 2026-03-17T06:24:47.469Z | F22: Sompartthana Bouphavong | H22: warehouse | I22: {=_xlfn.XLOOKUP(B22,Tickets!A:A,Tickets!A:A)} -> TKT-1773723473614
A23: act-1773735249639 | B23: TKT-1773723473614 | C23: Approved | D23: Approved | E23: 2026-03-17T08:14:04.089Z | F23: Jonathaan Meadley | H23: line_manager | I23: {=_xlfn.XLOOKUP(B23,Tickets!A:A,Tickets!A:A)} -> TKT-1773723473614
A24: act-1774339255173 | B24: TKT-1774339252579 | C24: Create | D24: Pending | E24: 2026-03-24T08:00:51.245Z | F24: Sompartthana Bouphavong | G24: Agency support Picky Bank 40 | I24: {=_xlfn.XLOOKUP(B24,Tickets!A:A,Tickets!A:A)} -> TKT-1774339252579
A25: act-1774339270072 | B25: TKT-1774339252579 | C25: Moved | D25: Moved | E25: 2026-03-24T08:01:06.719Z | F25: Sompartthana Bouphavong | H25: warehouse | I25: {=_xlfn.XLOOKUP(B25,Tickets!A:A,Tickets!A:A)} -> TKT-1774339252579
A26: act-1774339522860 | B26: TKT-1771577788359 | C26: Approved | D26: Approved | E26: 2026-03-24T08:05:19.378Z | F26: Souliphonh Phengxay | H26: director | I26: {=_xlfn.XLOOKUP(B26,Tickets!A:A,Tickets!A:A)} -> TKT-1771577788359
A27: act-1774339537654 | B27: TKT-1772507237246 | C27: Approved | D27: Approved | E27: 2026-03-24T08:05:34.964Z | F27: Souliphonh Phengxay | H27: director | I27: {=_xlfn.XLOOKUP(B27,Tickets!A:A,Tickets!A:A)} -> TKT-1772507237246
A28: act-1774339555053 | B28: TKT-1772592110294 | C28: Approved | D28: Approved | E28: 2026-03-24T08:05:52.128Z | F28: Souliphonh Phengxay | H28: director | I28: {=_xlfn.XLOOKUP(B28,Tickets!A:A,Tickets!A:A)} -> TKT-1772592110294
A29: act-1774339570245 | B29: TKT-1773299387291 | C29: Approved | D29: Approved | E29: 2026-03-24T08:06:06.664Z | F29: Souliphonh Phengxay | H29: director | I29: {=_xlfn.XLOOKUP(B29,Tickets!A:A,Tickets!A:A)} -> TKT-1773299387291
A30: act-1774339584028 | B30: TKT-1773652078809 | C30: Approved | D30: Approved | E30: 2026-03-24T08:06:21.012Z | F30: Souliphonh Phengxay | H30: director | I30: {=_xlfn.XLOOKUP(B30,Tickets!A:A,Tickets!A:A)} -> TKT-1773652078809
A31: act-1774339596804 | B31: TKT-1773722800507 | C31: Approved | D31: Approved | E31: 2026-03-24T08:06:33.410Z | F31: Souliphonh Phengxay | H31: director | I31: {=_xlfn.XLOOKUP(B31,Tickets!A:A,Tickets!A:A)} -> TKT-1773722800507
A32: act-1774339631577 | B32: TKT-1773723473614 | C32: Approved | D32: Approved | E32: 2026-03-24T08:07:06.618Z | F32: Souliphonh Phengxay | H32: director | I32: {=_xlfn.XLOOKUP(B32,Tickets!A:A,Tickets!A:A)} -> TKT-1773723473614
A33: act-1774419742599 | B33: TKT-1774339252579 | C33: Approved | D33: Approved | E33: 2026-03-25T06:22:21.582Z | F33: Jonathaan Meadley | H33: line_manager | I33: {=_xlfn.XLOOKUP(B33,Tickets!A:A,Tickets!A:A)} -> TKT-1774339252579
A34: act-1774431239689 | B34: TKT-1774431236031 | C34: Create | D34: Pending | E34: 2026-03-25T09:33:54.102Z | F34: Customer Service | G34: ເບີກເຄື່ອງໄວ່້ສາງຊັ້ນ6 | I34: {=_xlfn.XLOOKUP(B34,Tickets!A:A,Tickets!A:A)} -> TKT-1774431236031
A35: act-1774488920270 | B35: TKT-1774339252579 | C35: Approved | D35: Approved | E35: 2026-03-26T01:35:17.102Z | F35: Souliphonh Phengxay | H35: director | I35: {=_xlfn.XLOOKUP(B35,Tickets!A:A,Tickets!A:A)} -> TKT-1774339252579
A36: act-1774513871513 | B36: TKT-1774431236031 | C36: Moved | D36: Moved | E36: 2026-03-26T08:31:05.392Z | F36: Sompartthana Bouphavong | G36: ນ້ອງໆ CX ເບິກມາໄວ້ຊັ້ນ 6 ເພື່ອມອບໃຫ້ລູກຄ້າທີ່ເຂົ້າມາແລກຄະແນນ | H36: warehouse | I36: {=_xlfn.XLOOKUP(B36,Tickets!A:A,Tickets!A:A)} -> TKT-1774431236031
A37: act-1774519788051 | B37: TKT-1774431236031 | C37: Approved | D37: Approved | E37: 2026-03-26T10:09:44.990Z | F37: Jonathaan Meadley | H37: line_manager | I37: {=_xlfn.XLOOKUP(B37,Tickets!A:A,Tickets!A:A)} -> TKT-1774431236031
A38: act-1774519788956 | B38: TKT-1774519787325 | C38: Create | D38: Pending | E38: 2026-03-26T10:09:45.687Z | F38: Souk | G38: ເບີກໄວ້ມອບໃຫ້ຫົວໜ້າກົມເຕັກໂນໂລຊີ ແລະ ໄວໃຫ້ແຂກຫົວໜ້າ | I38: {=_xlfn.XLOOKUP(B38,Tickets!A:A,Tickets!A:A)} -> TKT-1774519787325
A39: act-1774519860981 | B39: TKT-1774519858761 | C39: Create | D39: Pending | E39: 2026-03-26T10:10:55.935Z | F39: Souk | G39: ໃຊ້ເປັນໂຕະກາເຟຊັ້ນ 01 ເພື່ອຮັບຮອງລູກຄ້າ | I39: {=_xlfn.XLOOKUP(B39,Tickets!A:A,Tickets!A:A)} -> TKT-1774519858761
A40: act-1774520416960 | B40: TKT-1774519787325 | C40: Moved | D40: Moved | E40: 2026-03-26T10:20:13.353Z | F40: Sompartthana Bouphavong | G40: ເນື່ອງຈາກ ສຸກຕ້ອງການດ່ວນ (ມື້ຊັບມິດເລີຍ) ກໍ່ເລີຍໃຫ້ສຸກເບິກຢືມນຳທີມ ບໍລິການລູກຄ້າກ່ອນ, ແລ້ວປູນາຈະເບິກມາແທນຄືນໃຫ້ | H40: warehouse | I40: {=_xlfn.XLOOKUP(B40,Tickets!A:A,Tickets!A:A)} -> TKT-1774519787325
...

Sheet Audit Tab
A1: SKU ID | B1: SKU Name | C1: Opening (Paper) | D1: Date Opening | E1: Stock In (Paper total) | F1: Stock Out System | G1: Expected Current | H1: Current in Sheet | I1: Variance | J1: Actual remaim
A2: sku-1771406960024 | B2: ບິກອີຊີໂກລ | C2: 850 | D2: 46073 | F2: =SUMIF(StockTransactions!C:C,A2,StockTransactions!D:D) -> 4350 | H2: {=_xlfn.XLOOKUP(A2,SKU_MasterData!A:A,SKU_MasterData!F:F)} -> 300 | J2: =C2-F2 -> -3500
A3: sku-1771407004896 | B3: ພວງກະເເຈ | C3: 474 | D3: 46073 | F3: =SUMIF(StockTransactions!C:C,A3,StockTransactions!D:D) -> 474 | H3: {=_xlfn.XLOOKUP(A3,SKU_MasterData!A:A,SKU_MasterData!F:F)} -> 0 | J3: =C3-F3 -> 0
A4: sku-1771407061986 | B4: ຈອກກາເເຟ | C4: 1637 | D4: 46073 | F4: =SUMIF(StockTransactions!C:C,A4,StockTransactions!D:D) -> 1382 | H4: {=_xlfn.XLOOKUP(A4,SKU_MasterData!A:A,SKU_MasterData!F:F)} -> 255 | J4: =C4-F4 -> 255
A5: sku-1771407101349 | B5: ຈອກເກັບຄວາມເຢັນ | C5: 176 | D5: 46073 | E5: 600 | F5: =SUMIF(StockTransactions!C:C,A5,StockTransactions!D:D) -> 1375 | H5: {=_xlfn.XLOOKUP(A5,SKU_MasterData!A:A,SKU_MasterData!F:F)} -> 0 | J5: =C5-F5 -> -1199
A6: sku-1771407148002 | B6: ກະເປົາຜ້າ | C6: 0 | D6: 46073 | F6: =SUMIF(StockTransactions!C:C,A6,StockTransactions!D:D) -> 0 | H6: {=_xlfn.XLOOKUP(A6,SKU_MasterData!A:A,SKU_MasterData!F:F)} -> 0 | J6: =C6-F6 -> 0
A7: sku-1771407316677 | B7: ຄັນຮົ່ມ 2026 | C7: 0 | D7: 46073 | E7: =200+200 -> 400 | F7: =SUMIF(StockTransactions!C:C,A7,StockTransactions!D:D) -> 800 | H7: {=_xlfn.XLOOKUP(A7,SKU_MasterData!A:A,SKU_MasterData!F:F)} -> 0 | J7: =C7-F7 -> -800
A8: sku-1771407810939 | B8: ກະປຸກອອມສິນ | C8: 392 | D8: 46073 | F8: =SUMIF(StockTransactions!C:C,A8,StockTransactions!D:D) -> 358 | H8: {=_xlfn.XLOOKUP(A8,SKU_MasterData!A:A,SKU_MasterData!F:F)} -> 34 | J8: =C8-F8 -> 34
A9: sku-1771407856341 | B9: ຫມວກ | C9: 0 | D9: 46073 | F9: =SUMIF(StockTransactions!C:C,A9,StockTransactions!D:D) -> 0 | H9: {=_xlfn.XLOOKUP(A9,SKU_MasterData!A:A,SKU_MasterData!F:F)} -> 0 | J9: =C9-F9 -> 0
A10: sku-1771407897767 | B10: ກະເປົາເດີນທາງ | C10: 1 | D10: 46073 | E10: 100 | F10: =SUMIF(StockTransactions!C:C,A10,StockTransactions!D:D) -> 301 | H10: {=_xlfn.XLOOKUP(A10,SKU_MasterData!A:A,SKU_MasterData!F:F)} -> 100 | J10: =C10-F10 -> -300
A11: sku-1771407936514 | B11: ຄັນຮົ່ມກ໊ອບ | C11: 98 | D11: 46073 | F11: =SUMIF(StockTransactions!C:C,A11,StockTransactions!D:D) -> 97 | H11: {=_xlfn.XLOOKUP(A11,SKU_MasterData!A:A,SKU_MasterData!F:F)} -> 1 | J11: =C11-F11 -> 1
A12: sku-1771407974256 | B12: ຊຸດຈອກກາເຟ | C12: 310 | D12: 46073 | F12: =SUMIF(StockTransactions!C:C,A12,StockTransactions!D:D) -> 170 | H12: {=_xlfn.XLOOKUP(A12,SKU_MasterData!A:A,SKU_MasterData!F:F)} -> 140 | J12: =C12-F12 -> 140
A13: sku-1771408020353 | B13: ຊຸດພິນ້ຽມ (ປື້ມ+ຕຸກນ້ຳ+ບິກ) | C13: 94 | D13: 46073 | F13: =SUMIF(StockTransactions!C:C,A13,StockTransactions!D:D) -> 114 | H13: {=_xlfn.XLOOKUP(A13,SKU_MasterData!A:A,SKU_MasterData!F:F)} -> 6 | J13: =C13-F13 -> -20
A14: sku-1772007048630 | B14: ໂຕະຂາວ (ແບບພັບ) W180 x H75 x L60cm | C14: 3 | D14: 46073 | F14: =SUMIF(StockTransactions!C:C,A14,StockTransactions!D:D) -> 1 | H14: {=_xlfn.XLOOKUP(A14,SKU_MasterData!A:A,SKU_MasterData!F:F)} -> 2 | J14: =C14-F14 -> 2
A15: sku-1772007441977 | B15: ຕັ່ງພັບ ສີຟ້າ | C15: 8 | D15: 46073 | F15: =SUMIF(StockTransactions!C:C,A15,StockTransactions!D:D) -> 0 | H15: {=_xlfn.XLOOKUP(A15,SKU_MasterData!A:A,SKU_MasterData!F:F)} -> 8 | J15: =C15-F15 -> 8
A16: sku-1772168083653 | B16: A4 Acrylic Sign Holder | C16: 10 | D16: 46073 | F16: =SUMIF(StockTransactions!C:C,A16,StockTransactions!D:D) -> 0 | H16: {=_xlfn.XLOOKUP(A16,SKU_MasterData!A:A,SKU_MasterData!F:F)} -> 10 | J16: =C16-F16 -> 10
A17: sku-1772179915959 | B17: ແບັກດອບແບບຜ້າ 230 WxH 200 cm | C17: 2 | D17: 46073 | F17: =SUMIF(StockTransactions!C:C,A17,StockTransactions!D:D) -> 2 | H17: {=_xlfn.XLOOKUP(A17,SKU_MasterData!A:A,SKU_MasterData!F:F)} -> 0 | J17: =C17-F17 -> 0
A18: sku-1772183466273 | B18: ໂຕະເຄົາເຕີ Fabric Counter ຂະຫນາດ: W 75x H 150 Cm | C18: 2 | D18: 46073 | F18: =SUMIF(StockTransactions!C:C,A18,StockTransactions!D:D) -> 0 | H18: {=_xlfn.XLOOKUP(A18,SKU_MasterData!A:A,SKU_MasterData!F:F)} -> 2 | J18: =C18-F18 -> 2
A19: sku-1772183613706 | B19: Beach flag 310x240x60 Cm | C19: 2 | D19: 46073 | F19: =SUMIF(StockTransactions!C:C,A19,StockTransactions!D:D) -> 0 | H19: {=_xlfn.XLOOKUP(A19,SKU_MasterData!A:A,SKU_MasterData!F:F)} -> 2 | J19: =C19-F19 -> 2
A20: sku-1772183974356 | B20: TV 52 ນິ້ວ | C20: 1 | D20: 46073 | F20: =SUMIF(StockTransactions!C:C,A20,StockTransactions!D:D) -> 0 | H20: {=_xlfn.XLOOKUP(A20,SKU_MasterData!A:A,SKU_MasterData!F:F)} -> 1 | J20: =C20-F20 -> 1
A21: sku-1773299233699 | B21: A4 Brochure | C21: 5000 | D21: 46073 | F21: =SUMIF(StockTransactions!C:C,A21,StockTransactions!D:D) -> 4700 | H21: {=_xlfn.XLOOKUP(A21,SKU_MasterData!A:A,SKU_MasterData!F:F)} -> 300 | J21: =C21-F21 -> 300
A22: sku-1773828255894 | B22: JBL Speaker | C22: 1 | D22: 46073 | F22: =SUMIF(StockTransactions!C:C,A22,StockTransactions!D:D) -> 3 | H22: {=_xlfn.XLOOKUP(A22,SKU_MasterData!A:A,SKU_MasterData!F:F)} -> 2 | J22: =C22-F22 -> -2
... A24: sku-1775030479680 | B24: ສາຍຮັດແຂນ (ກິລາ) | C24: 400 | D24: 46112 | F24: =SUMIF(StockTransactions!C:C,A24,StockTransactions!D:D) -> 315 | H24: {=_xlfn.XLOOKUP(A24,SKU_MasterData!A:A,SKU_MasterData!F:F)} -> 85 | J24: =C24-F24 -> 85
A25: sku-1775030698487 | B25: ສາຍຫ້ອຍຄໍ (ພວງກະແຈ) | C25: 2000 | D25: 46112 | F25: =SUMIF(StockTransactions!C:C,A25,StockTransactions!D:D) -> 1750 | H25: {=_xlfn.XLOOKUP(A25,SKU_MasterData!A:A,SKU_MasterData!F:F)} -> 250 | J25: =C25-F25 -> 250 | L25: 950 | M25: =L25-F25 -> -800
A26: sku-1775456004647 | B26: ກະເປົາກິລາ | C26: 600 | D26: 46118 | F26: =SUMIF(StockTransactions!C:C,A26,StockTransactions!D:D) -> 390 | H26: {=_xlfn.XLOOKUP(A26,SKU_MasterData!A:A,SKU_MasterData!F:F)} -> 210 | J26: =C26-F26 -> 210
